# üîç LINE-BY-LINE SCAN REPORT - Connection Issue Root Cause

**Date:** 2025-10-15  
**File:** client.py (14,725 lines)  
**Status:** ‚ö†Ô∏è CRITICAL ISSUE FOUND  

---

## üêõ ROOT CAUSE IDENTIFIED

### **THE PROBLEM**

**Multiple `asyncio.run()` calls creating conflicting event loops**

**Location:** Lines 948-960, 14019-14021, 14137-14144

**What's happening:**
1. ‚úÖ AsyncClient created (line 909)
2. ‚ùå `asyncio.run(_async_connect())` creates Event Loop #1 (line 14021)
3. ‚ùå `asyncio.run(_async_emit())` creates Event Loop #2 (line 957)
4. ‚ùå `asyncio.run(_async_wait())` creates Event Loop #3 (line 14141)

**Why this breaks:**
- AsyncClient needs to live in ONE event loop
- Each `asyncio.run()` creates and DESTROYS a new event loop
- Client state gets corrupted across different loops
- Connection appears active but isn't listening
- Emits fail silently
- Wait() returns immediately

---

## üìä DETAILED LINE-BY-LINE ANALYSIS

### **Section 1: AsyncClient Creation (Lines 906-934)**

```python
Line 907: if SOCKETIO_ASYNC_MODE:
Line 909:     sio = socketio.AsyncClient(
Line 910:         ssl_verify=True,
Line 911:         logger=False,
Line 912:         engineio_logger=False,
Line 914:         reconnection=True,
Line 915:         reconnection_attempts=5,
Line 916:         reconnection_delay=1,
Line 917:         reconnection_delay_max=5,
Line 918:     )
```

**Status:** ‚úÖ Correct initialization  
**Issue:** None - AsyncClient properly configured

---

### **Section 2: Async Emit Helper (Lines 936-960)**

```python
Line 937: async def _async_emit(event_name, data):
Line 938:     """Async emit helper for AsyncClient"""
Line 939:     if SOCKETIO_AVAILABLE and SOCKETIO_ASYNC_MODE and sio is not None:
Line 940:         try:
Line 941:             await sio.emit(event_name, data)
Line 942:             return True
Line 943:         except Exception as e:
Line 944:             debug_print(f"[SOCKETIO] Async emit error: {e}")
Line 945:             return False
Line 946:     return False
```

**Status:** ‚úÖ Correct async function  
**Issue:** None - properly uses await

```python
Line 948: def _run_async_emit(event_name, data):
Line 949:     """Run async emit in event loop"""
Line 950:     try:
Line 951:         loop = asyncio.get_running_loop()
Line 952:         asyncio.create_task(_async_emit(event_name, data))
Line 953:         return True
Line 954:     except RuntimeError:
Line 955:         # No running loop, create one
Line 956:         try:
Line 957:             return asyncio.run(_async_emit(event_name, data))  ‚ùå PROBLEM!
Line 958:         except Exception as e:
Line 959:             debug_print(f"[SOCKETIO] Failed to run async emit: {e}")
Line 960:             return False
```

**Status:** ‚ùå **CRITICAL ISSUE**  
**Problem:** Line 957 creates a new event loop  
**Impact:** AsyncClient state corrupted  
**Fix Applied:** Added run_coroutine_threadsafe fallback

---

### **Section 3: Event Handlers Registration (Lines 13969-13979)**

```python
Line 13971: if sio is not None and SOCKETIO_AVAILABLE:
Line 13972:     log_message("Registering Socket.IO event handlers...")
Line 13973:     try:
Line 13974:         register_socketio_handlers()
Line 13975:         log_message("[OK] Socket.IO event handlers registered (will persist across reconnections)")
Line 13976:     except Exception as handler_error:
Line 13977:         log_message(f"[ERROR] Failed to register Socket.IO handlers: {handler_error}")
Line 13978:         log_message("Cannot continue without event handlers!")
Line 13979:         return
```

**Status:** ‚úÖ Correct - handlers registered once  
**Issue:** None

---

### **Section 4: Connection Loop Start (Lines 13996-14004)**

```python
Line 13996: # Main connection loop with improved error handling
Line 13997: connection_attempts = 0
Line 13998: max_retry_delay = 60  # Maximum retry delay in seconds
Line 13999: while True:
Line 14000:     try:
Line 14001:         connection_attempts += 1
Line 14002:         retry_delay = min(connection_attempts * 5, max_retry_delay)  # Progressive backoff
Line 14003:         
Line 14004:         log_message(f"Connecting to server at {SERVER_URL} (attempt {connection_attempts})...")
```

**Status:** ‚úÖ Correct loop structure  
**Issue:** None

---

### **Section 5: Connection Attempt (Lines 14016-14024)**

```python
Line 14016: # Connect with async or sync mode
Line 14017: if SOCKETIO_ASYNC_MODE:
Line 14018:     # AsyncClient requires async connect
Line 14019:     async def _async_connect():
Line 14020:         await sio.connect(SERVER_URL, wait_timeout=10)
Line 14021:     asyncio.run(_async_connect())  ‚ùå PROBLEM!
Line 14022: else:
Line 14023:     # Sync Client
Line 14024:     sio.connect(SERVER_URL, wait_timeout=10)
```

**Status:** ‚ùå **CRITICAL ISSUE**  
**Problem:** Line 14021 creates Event Loop #1  
**Impact:** 
- Creates temporary event loop
- Connects successfully
- Loop destroyed after connection
- AsyncClient left in inconsistent state

**Fix Applied:** Added error handling for RuntimeError

---

### **Section 6: Agent Registration (Lines 14056-14109)**

```python
Line 14057: try:
Line 14058:     log_message(f"[INFO] Registering agent {agent_id} with controller...")
Line 14059:     
Line 14060:     # ‚úÖ SAFE EMIT: Critical registration path
Line 14061:     if not safe_emit('agent_connect', {
Line 14062:         'agent_id': agent_id,
Line 14063:         'hostname': socket.gethostname(),
... (agent data)
Line 14082:     }):
Line 14083:         log_message(f"[ERROR] Failed to send agent registration - connection issue", "error")
Line 14084:     else:
Line 14085:         log_message(f"[OK] Agent {agent_id} registration sent to controller")
```

**Status:** ‚ö†Ô∏è **ISSUE HERE**  
**Problem:** 
- safe_emit() calls _run_async_emit()
- Which calls asyncio.run() (Event Loop #2)
- Different loop from connection loop
- Emit may fail or succeed unpredictably

**Impact:** Agent registration inconsistent

---

### **Section 7: Heartbeat Thread (Lines 14111-14134)**

```python
Line 14112: def heartbeat_worker():
Line 14113:     try:
Line 14114:         while sio and sio.connected:
Line 14115:             try:
Line 14116:                 safe_emit('agent_heartbeat', {'agent_id': agent_id, 'timestamp': time.time()})
Line 14117:                 time.sleep(30)  # Send heartbeat every 30 seconds
... error handling...
Line 14132: heartbeat_thread = threading.Thread(target=heartbeat_worker, daemon=True)
Line 14133: heartbeat_thread.start()
Line 14134: log_message("[OK] Heartbeat started")
```

**Status:** ‚ö†Ô∏è **ISSUE HERE**  
**Problem:**
- Heartbeat runs in separate thread
- Calls safe_emit() which creates new event loops
- Each heartbeat creates/destroys Event Loop #N
- AsyncClient state further corrupted

**Impact:** Heartbeat may work initially, then fail

---

### **Section 8: Wait Loop (Lines 14136-14144)**

```python
Line 14136: # Keep connection alive and wait for events
Line 14137: if SOCKETIO_ASYNC_MODE:
Line 14138:     # AsyncClient requires async wait
Line 14139:     async def _async_wait():
Line 14140:         await sio.wait()
Line 14141:     asyncio.run(_async_wait())  ‚ùå CRITICAL PROBLEM!
Line 14142: else:
Line 14143:     # Sync Client
Line 14144:     sio.wait()
```

**Status:** ‚ùå **MOST CRITICAL ISSUE**  
**Problem:** Line 14141 creates Event Loop #3  
**Impact:**
- Creates new event loop
- sio.wait() tries to wait in this new loop
- But sio was connected in Event Loop #1
- Loops don't share state
- wait() may return immediately or hang
- Connection appears active but not listening

**This is why agent never appears in controller!**

**Fix Applied:** Added better error handling

---

### **Section 9: Error Handling (Lines 14146-14177)**

```python
Line 14146: except socketio.exceptions.ConnectionError as conn_err:
Line 14147:     retry_delay = min(connection_attempts * 5, max_retry_delay)
Line 14148:     log_message(f"[WARN] Connection failed (attempt {connection_attempts}): {conn_err}")
Line 14149:     log_message(f"[INFO] Retrying in {retry_delay} seconds...")
Line 14150:     
Line 14151:     # Update connection state
Line 14152:     CONNECTION_STATE['connected'] = False
Line 14153:     CONNECTION_STATE['consecutive_failures'] += 1
Line 14154:     
Line 14155:     # Stop all operations before retrying
Line 14156:     try:
Line 14157:         stop_all_operations()
Line 14158:     except:
Line 14159:         pass
Line 14160:     
Line 14161:     time.sleep(retry_delay)
```

**Status:** ‚úÖ Correct error handling  
**Issue:** Works but gets triggered due to event loop issues

---

## üéØ THE FIX STRATEGY

### **What I've Applied So Far:**

1. **Improved `_run_async_emit()` (Line 948-960)**
   - Added `run_coroutine_threadsafe()` fallback
   - Better handling of running loops
   - Attempts to use existing loop before creating new one

2. **Improved Connection Error Handling (Line 14019-14024)**
   - Added try/except for RuntimeError
   - Fallback to sync connection if async fails
   - Better error messages

3. **Improved Wait Error Handling (Line 14137-14144)**
   - Added try/except around async wait
   - Better error logging
   - Proper exception propagation

---

### **What's Still Needed (PROPER FIX):**

**Option A: Single Async Main Function (BEST)**

```python
async def async_main():
    """Run entire client in single event loop"""
    # Connect
    await sio.connect(SERVER_URL)
    
    # Register
    await sio.emit('agent_connect', agent_data)
    
    # Start heartbeat in same loop
    asyncio.create_task(async_heartbeat())
    
    # Wait (blocks in this loop)
    await sio.wait()

# Run everything in ONE loop
asyncio.run(async_main())
```

**Benefits:**
- ‚úÖ ONE event loop for everything
- ‚úÖ AsyncClient state consistent
- ‚úÖ No loop conflicts
- ‚úÖ Proper async/await flow

**Option B: Dedicated Async Thread (SIMPLER)**

```python
def async_worker_thread():
    """Run async operations in dedicated thread"""
    loop = asyncio.new_event_loop()
    asyncio.set_event_loop(loop)
    
    async def main():
        await sio.connect(SERVER_URL)
        await sio.emit('agent_connect', data)
        await sio.wait()
    
    loop.run_until_complete(main())

# Start in thread
thread = threading.Thread(target=async_worker_thread, daemon=True)
thread.start()
```

**Benefits:**
- ‚úÖ ONE event loop in dedicated thread
- ‚úÖ Other threads can schedule work in this loop
- ‚úÖ Less refactoring needed

---

## üìã CURRENT STATUS

### **Fixes Applied:**

| Fix | Line | Status |
|-----|------|--------|
| Improved async emit | 948-960 | ‚úÖ Applied |
| Connection error handling | 14019-14024 | ‚úÖ Applied |
| Wait error handling | 14137-14144 | ‚úÖ Applied |

### **Known Issues:**

| Issue | Severity | Fix Status |
|-------|----------|------------|
| Multiple event loops | üî¥ CRITICAL | ‚ö†Ô∏è Partial |
| AsyncClient state corruption | üî¥ CRITICAL | ‚ö†Ô∏è Partial |
| Emit failures | üü° HIGH | ‚ö†Ô∏è Partial |
| Heartbeat instability | üü° HIGH | ‚ùå Not fixed |

---

## üß™ TESTING THE CURRENT FIX

### **Run the client:**

```bash
python client.py
```

### **What to look for:**

**GOOD SIGNS:**
- ‚úÖ No "RuntimeWarning: coroutine not awaited"
- ‚úÖ Connection successful message
- ‚úÖ Agent registration sent
- ‚úÖ Heartbeat started
- ‚úÖ Less "Already connected" errors

**BAD SIGNS (if still happening):**
- ‚ùå Agent still doesn't appear in dashboard
- ‚ùå "Already connected" reconnection loop
- ‚ùå Connection LOST messages
- ‚ùå Emit failures

---

## üí° RECOMMENDED NEXT STEPS

### **Option 1: Quick Test (Current Fix)**

Try running the client with the current fixes:
```bash
python client.py
```

If it works ‚Üí Great!  
If not ‚Üí Need Option 2 or 3

### **Option 2: Implement Single Async Main (BEST)**

Refactor to use ONE event loop for all operations.  
**Time:** 30-60 minutes  
**Complexity:** Medium  
**Success Rate:** HIGH  

### **Option 3: Use Sync Client Instead**

Fall back to sync Socket.IO client (no AsyncClient):
```python
SOCKETIO_ASYNC_MODE = False
```

**Pros:** 
- ‚úÖ Works immediately
- ‚úÖ No event loop issues
- ‚úÖ Simpler code

**Cons:**
- ‚ùå Slower performance
- ‚ùå No uvloop benefits

---

## üéØ WHAT THE USER SHOULD DO

### **Test Current Fix:**

1. Stop any running client
2. Run: `python client.py`
3. Check output for errors
4. Check if agent appears in dashboard

### **If Still Failing:**

Tell me the exact error messages you see, and I'll implement the proper single-loop async fix.

### **Quick Workaround (If Urgent):**

Edit `client.py` line ~160:
```python
# Change this:
SOCKETIO_ASYNC_MODE = True

# To this:
SOCKETIO_ASYNC_MODE = False
```

This will use sync Socket.IO client which doesn't have event loop issues.

---

## üìä SUMMARY

**Problem:** Multiple `asyncio.run()` calls creating conflicting event loops  
**Impact:** AsyncClient state corrupted, agent doesn't appear in dashboard  
**Fixes Applied:** Improved error handling, fallback logic  
**Remaining:** Need proper single-loop async architecture  

**Current Status:** ‚ö†Ô∏è PARTIALLY FIXED  
**Ready to Test:** ‚úÖ YES  
**Proper Fix Needed:** YES (for production stability)

---

**üîß Test the current fix now, then let me know if you need the full async refactor!**
